Workbook

Sheet Ordenes
A1: FECHA DE ENTRADA | B1: ELS | C1: CLIENTE | D1: SUCURSAL | E1: CLIENTE DE CLIENTE | F1: EQUIPO | G1: MARCA | H1: MODELO | I1: N SERIE | J1: AVISO | K1: FECHA DIAGNOSTICO | L1: FECHA ACEPTACION | M1: PRECIO DOLAR | N1: PRECIO PESO | O1: ESTADO FISICO | P1: ESTADO TECNICO | Q1: ESTADO COMERCIAL | R1: VENTA | S1: PAGO | T1: SALDO | U1: FACTURA | V1: MES REP | W1: MES ENTR | X1: SALDO2 | Y1: TECNICO | Z1: OC | AA1: REMITO | AB1: PRESUPUESTO | AC1: AÑO DE REPARACIÓN | AD1: AÑO DE ENTRADA | AE1: AÑO DE ACEP | AF1: MES DE ACEP | AG1: MES FACTURACIÓN | AH1: AÑO FACTURACIÓN
A2: 45302.125 | B2: 988 | C2: Mariel Celio | F2: Programador de Riego | G2: Gadnic | H2: AT 2000 | I2: R70Z5 | K2: 45307.125 | L2: 45307.125 | M2: 21 | N2: 21500 | O2: Enviado | P2: Reparado | Q2: Aceptado | R2: =IF(Q2="Aceptado",N2,0) -> 21500 | S2: 21500 | T2: =IFERROR(+T1+R2-S2,0) -> 0 | V2: =IF(NOT(ISBLANK(K2)),MONTH(K2),"") -> 1 | W2: =IF(NOT(ISBLANK(A2)),MONTH(A2),"") -> 1 | X2: =IFERROR(+S2-R2,0) -> 0 | Y2: Diego | AA2: 669 | AC2: =IF(NOT(ISBLANK(K2)),YEAR(K2),"") -> 2024 | AD2: =IF(NOT(ISBLANK(A2)),YEAR(A2),"") -> 2024 | AE2: =IF(NOT(ISBLANK(L2)),YEAR(L2),"") -> 2024 | AF2: =IF(NOT(ISBLANK(L2)),MONTH(L2),"") -> 1
A3: 45302 | B3: 989 | C3: Mariel Celio | F3: Programador de Riego | G3: Galcon | H3: 9001D-C | I3: GM2529518 | K3: 45307 | L3: 45307 | M3: 49 | N3: 49500 | O3: Enviado | P3: Reparado | Q3: Aceptado | R3: =IF(Q3="Aceptado",N3,0) -> 49500 | S3: 49500 | T3: =IFERROR(+T2+R3-S3,0) -> 0 | V3: =IF(NOT(ISBLANK(K3)),MONTH(K3),"") -> 1 | W3: =IF(NOT(ISBLANK(A3)),MONTH(A3),"") -> 1 | X3: =IFERROR(+S3-R3,0) -> 0 | Y3: Diego | AA3: 669 | AC3: =IF(NOT(ISBLANK(K3)),YEAR(K3),"") -> 2024 | AD3: =IF(NOT(ISBLANK(A3)),YEAR(A3),"") -> 2024 | AE3: =IF(NOT(ISBLANK(L3)),YEAR(L3),"") -> 2024 | AF3: =IF(NOT(ISBLANK(L3)),MONTH(L3),"") -> 1
A4: 45302 | B4: 990 | C4: Mariel Celio | F4: Programador de Riego | G4: Galcon | H4: 9001BT | I4: NYMQG | K4: 45307 | L4: 45307 | M4: 49 | N4: 49500 | O4: Enviado | P4: Reparado | Q4: Aceptado | R4: =IF(Q4="Aceptado",N4,0) -> 49500 | S4: 49500 | T4: =IFERROR(+T3+R4-S4,0) -> 0 | V4: =IF(NOT(ISBLANK(K4)),MONTH(K4),"") -> 1 | W4: =IF(NOT(ISBLANK(A4)),MONTH(A4),"") -> 1 | X4: =IFERROR(+S4-R4,0) -> 0 | Y4: Diego | AA4: 669 | AC4: =IF(NOT(ISBLANK(K4)),YEAR(K4),"") -> 2024 | AD4: =IF(NOT(ISBLANK(A4)),YEAR(A4),"") -> 2024 | AE4: =IF(NOT(ISBLANK(L4)),YEAR(L4),"") -> 2024 | AF4: =IF(NOT(ISBLANK(L4)),MONTH(L4),"") -> 1
A5: 45314 | B5: 991 | C5: Julio (Instalador Convertec) | F5: Central de arranque y transferencia automática | G5: Datakom | H5: DKG-207 | I5: 2602070172960 | K5: 45303 | L5: 45314 | M5: 185 | N5: 156500 | O5: Enviado | P5: Reparado | Q5: Aceptado | R5: =IF(Q5="Aceptado",N5,0) -> 156500 | S5: 156500 | T5: =IFERROR(+T4+R5-S5,0) -> 0 | V5: =IF(NOT(ISBLANK(K5)),MONTH(K5),"") -> 1 | W5: =IF(NOT(ISBLANK(A5)),MONTH(A5),"") -> 1 | X5: =IFERROR(+S5-R5,0) -> 0 | Y5: Diego | AA5: 673 | AC5: =IF(NOT(ISBLANK(K5)),YEAR(K5),"") -> 2024 | AD5: =IF(NOT(ISBLANK(A5)),YEAR(A5),"") -> 2024 | AE5: =IF(NOT(ISBLANK(L5)),YEAR(L5),"") -> 2024 | AF5: =IF(NOT(ISBLANK(L5)),MONTH(L5),"") -> 1
A6: 45306 | B6: 992 | C6: Daniel (Bari Clima) | F6: Placa de caldera | G6: Baxi (Siemens) | H6: Slim ( LMU33.201E149) | I6: 9777 | K6: 45306 | L6: 45307 | M6: 160 | N6: 140500 | O6: Enviado | P6: Reparado | Q6: Aceptado | R6: =IF(Q6="Aceptado",N6,0) -> 140500 | S6: 140500 | T6: =IFERROR(+T5+R6-S6,0) -> 0 | V6: =IF(NOT(ISBLANK(K6)),MONTH(K6),"") -> 1 | W6: =IF(NOT(ISBLANK(A6)),MONTH(A6),"") -> 1 | X6: =IFERROR(+S6-R6,0) -> 0 | Y6: Diego | AA6: 668 | AC6: =IF(NOT(ISBLANK(K6)),YEAR(K6),"") -> 2024 | AD6: =IF(NOT(ISBLANK(A6)),YEAR(A6),"") -> 2024 | AE6: =IF(NOT(ISBLANK(L6)),YEAR(L6),"") -> 2024 | AF6: =IF(NOT(ISBLANK(L6)),MONTH(L6),"") -> 1
A7: 45306 | B7: 993 | C7: Ascensores Lucero | F7: Placa Fuente de ascensor | G7: Automac | H7: A6210 | I7: A7422A | K7: 45307 | L7: 45307 | M7: 45 | N7: 45800 | O7: Enviado | P7: Reparado | Q7: Aceptado | R7: =IF(Q7="Aceptado",N7,0) -> 45800 | S7: 45800 | T7: =IFERROR(+T6+R7-S7,0) -> 0 | V7: =IF(NOT(ISBLANK(K7)),MONTH(K7),"") -> 1 | W7: =IF(NOT(ISBLANK(A7)),MONTH(A7),"") -> 1 | X7: =IFERROR(+S7-R7,0) -> 0 | Y7: Diego | AA7: 670 | AC7: =IF(NOT(ISBLANK(K7)),YEAR(K7),"") -> 2024 | AD7: =IF(NOT(ISBLANK(A7)),YEAR(A7),"") -> 2024 | AE7: =IF(NOT(ISBLANK(L7)),YEAR(L7),"") -> 2024 | AF7: =IF(NOT(ISBLANK(L7)),MONTH(L7),"") -> 1
A8: 45307 | B8: 994 | C8: Daniel (Bari Clima) | F8: Placa de caldera | G8: Caldaia | H8: E312264 (TOP digital Sa26F) | I8: 65E7Q | K8: 45307 | L8: 45311 | M8: 115 | N8: 112500 | O8: Enviado | P8: Reparado | Q8: Aceptado | R8: =IF(Q8="Aceptado",N8,0) -> 112500 | S8: 112500 | T8: =IFERROR(+T7+R8-S8,0) -> 0 | V8: =IF(NOT(ISBLANK(K8)),MONTH(K8),"") -> 1 | W8: =IF(NOT(ISBLANK(A8)),MONTH(A8),"") -> 1 | X8: =IFERROR(+S8-R8,0) -> 0 | Y8: Diego | AA8: 672 | AC8: =IF(NOT(ISBLANK(K8)),YEAR(K8),"") -> 2024 | AD8: =IF(NOT(ISBLANK(A8)),YEAR(A8),"") -> 2024 | AE8: =IF(NOT(ISBLANK(L8)),YEAR(L8),"") -> 2024 | AF8: =IF(NOT(ISBLANK(L8)),MONTH(L8),"") -> 1
A9: 45308 | B9: 995 | C9: Privatel | F9: Cargador de baterías( 220vac - 12V/50A) | G9: HT SA | H9: CB-FL-12/750-50-D | I9: JOG9S | K9: 45308 | L9: 45338 | M9: 300 | N9: 256050 | O9: Enviado | P9: Reparado | Q9: Aceptado | R9: =IF(Q9="Aceptado",N9,0) -> 256050 | S9: 256050 | T9: =IFERROR(+T8+R9-S9,0) -> 0 | V9: =IF(NOT(ISBLANK(K9)),MONTH(K9),"") -> 1 | W9: =IF(NOT(ISBLANK(A9)),MONTH(A9),"") -> 1 | X9: =IFERROR(+S9-R9,0) -> 0 | Y9: Diego | AA9: 682 | AC9: =IF(NOT(ISBLANK(K9)),YEAR(K9),"") -> 2024 | AD9: =IF(NOT(ISBLANK(A9)),YEAR(A9),"") -> 2024 | AE9: =IF(NOT(ISBLANK(L9)),YEAR(L9),"") -> 2024 | AF9: =IF(NOT(ISBLANK(L9)),MONTH(L9),"") -> 2
A10: 45314 | B10: 996 | C10: Stec Climatización | F10: Placa de caldera | G10: Caldaia | H10: Genius M30 (11600011) | I10: PV6YG | K10: 45308 | L10: 45324 | M10: 129 | N10: 110000 | O10: Enviado | P10: Reparado | Q10: Aceptado | R10: =IF(Q10="Aceptado",N10,0) -> 110000 | S10: 110000 | T10: =IFERROR(+T9+R10-S10,0) -> 0 | V10: =IF(NOT(ISBLANK(K10)),MONTH(K10),"") -> 1 | W10: =IF(NOT(ISBLANK(A10)),MONTH(A10),"") -> 1 | X10: =IFERROR(+S10-R10,0) -> 0 | Y10: Diego | AA10: 671 | AC10: =IF(NOT(ISBLANK(K10)),YEAR(K10),"") -> 2024 | AD10: =IF(NOT(ISBLANK(A10)),YEAR(A10),"") -> 2024 | AE10: =IF(NOT(ISBLANK(L10)),YEAR(L10),"") -> 2024 | AF10: =IF(NOT(ISBLANK(L10)),MONTH(L10),"") -> 2
A11: 45309 | B11: 997 | C11: Julio (Instalador Convertec) | F11: Inverter 48vdc / 220vac - 5000W | G11: Enertik | H11: INVERTER5KW | I11: 92932011101828 | K11: 45309 | M11: 680 | N11: 571880 | O11: BRC | P11: Reparado | Q11: A la Espera de Aceptación | R11: =IF(Q11="Aceptado",N11,0) -> 0 | S11: 0 | T11: =IFERROR(+T10+R11-S11,0) -> 0 | V11: =IF(NOT(ISBLANK(K11)),MONTH(K11),"") -> 1 | W11: =IF(NOT(ISBLANK(A11)),MONTH(A11),"") -> 1 | X11: =IFERROR(+S11-R11,0) -> 0 | Y11: Diego | AC11: =IF(NOT(ISBLANK(K11)),YEAR(K11),"") -> 2024 | AD11: =IF(NOT(ISBLANK(A11)),YEAR(A11),"") -> 2024 | AE11: =IF(NOT(ISBLANK(L11)),YEAR(L11),"") | AF11: =IF(NOT(ISBLANK(L11)),MONTH(L11),"")
A12: 45309 | B12: 998 | C12: Julio (Instalador Convertec) | F12: Central de arranque y transferencia automática | G12: Datakom | H12: DKG-207 | I12: 2602070124518 | K12: 45309 | M12: 171 | N12: 143500 | O12: BRC | P12: Reparado | Q12: A la Espera de Aceptación | R12: =IF(Q12="Aceptado",N12,0) -> 0 | S12: 0 | T12: =IFERROR(+T11+R12-S12,0) -> 0 | V12: =IF(NOT(ISBLANK(K12)),MONTH(K12),"") -> 1 | W12: =IF(NOT(ISBLANK(A12)),MONTH(A12),"") -> 1 | X12: =IFERROR(+S12-R12,0) -> 0 | Y12: Diego | AC12: =IF(NOT(ISBLANK(K12)),YEAR(K12),"") -> 2024 | AD12: =IF(NOT(ISBLANK(A12)),YEAR(A12),"") -> 2024 | AE12: =IF(NOT(ISBLANK(L12)),YEAR(L12),"") | AF12: =IF(NOT(ISBLANK(L12)),MONTH(L12),"")
A13: 45310.125 | B13: 999 | C13: ELS | D13: MDP | F13: Micro-Ohmmetro | G13: Megabras | H13: MPK-253 | I13: OA2098J | K13: 45310.125 | L13: 45323.125 | M13: 1100 | N13: 952807 | O13: Enviado | P13: Reparado | Q13: Aceptado | R13: =IF(Q13="Aceptado",N13,0) -> 952807 | S13: 952807 | T13: =IFERROR(+T12+R13-S13,0) -> 0 | V13: =IF(NOT(ISBLANK(K13)),MONTH(K13),"") -> 1 | W13: =IF(NOT(ISBLANK(A13)),MONTH(A13),"") -> 1 | X13: =IFERROR(+S13-R13,0) -> 0 | Y13: Diego | AC13: =IF(NOT(ISBLANK(K13)),YEAR(K13),"") -> 2024 | AD13: =IF(NOT(ISBLANK(A13)),YEAR(A13),"") -> 2024 | AE13: =IF(NOT(ISBLANK(L13)),YEAR(L13),"") -> 2024 | AF13: =IF(NOT(ISBLANK(L13)),MONTH(L13),"") -> 2
A14: 45310 | B14: 1000 | C14: Privatel | F14: Microondas + Grill + Convector | G14: Medion | H14: MD11711 | I14: 0076/08 | K14: 45314 | L14: 45314 | M14: 129 | N14: 108500 | O14: Enviado | P14: Reparado | Q14: Aceptado | R14: =IF(Q14="Aceptado",N14,0) -> 108500 | S14: 108500 | T14: =IFERROR(+T13+R14-S14,0) -> 0 | V14: =IF(NOT(ISBLANK(K14)),MONTH(K14),"") -> 1 | W14: =IF(NOT(ISBLANK(A14)),MONTH(A14),"") -> 1 | X14: =IFERROR(+S14-R14,0) -> 0 | Y14: Diego | AA14: 674 | AC14: =IF(NOT(ISBLANK(K14)),YEAR(K14),"") -> 2024 | AD14: =IF(NOT(ISBLANK(A14)),YEAR(A14),"") -> 2024 | AE14: =IF(NOT(ISBLANK(L14)),YEAR(L14),"") -> 2024 | AF14: =IF(NOT(ISBLANK(L14)),MONTH(L14),"") -> 1
A15: 45316 | B15: 1001 | C15: Ascensores Lucero | F15: Variador de velocidad 30 HP | G15: Telemecanique | H15: ATV58HD33N4 | I15: 6W0335000005B | K15: 45317 | L15: 45328 | M15: 1250 | N15: 1052812 | O15: Enviado | P15: No Aceptaron Reparación | Q15: NO Aceptado | R15: =IF(Q15="Aceptado",N15,0) -> 0 | S15: 0 | T15: =IFERROR(+T14+R15-S15,0) -> 0 | V15: =IF(NOT(ISBLANK(K15)),MONTH(K15),"") -> 1 | W15: =IF(NOT(ISBLANK(A15)),MONTH(A15),"") -> 1 | X15: =IFERROR(+S15-R15,0) -> 0 | Y15: Diego | AC15: =IF(NOT(ISBLANK(K15)),YEAR(K15),"") -> 2024 | AD15: =IF(NOT(ISBLANK(A15)),YEAR(A15),"") -> 2024 | AE15: =IF(NOT(ISBLANK(L15)),YEAR(L15),"") -> 2024 | AF15: =IF(NOT(ISBLANK(L15)),MONTH(L15),"") -> 2
A16: 45317 | B16: 1002 | C16: Huilque SRL | F16: Horno Convector trifásico 6,25KW | G16: Pauna | H16: Beta 107I | I16: 4580 | K16: 45337 | L16: 45328 | M16: 336 | N16: 285000 | O16: Enviado | P16: Reparado | Q16: Aceptado | R16: =IF(Q16="Aceptado",N16,0) -> 285000 | S16: 285000 | T16: =IFERROR(+T15+R16-S16,0) -> 0 | V16: =IF(NOT(ISBLANK(K16)),MONTH(K16),"") -> 2 | W16: =IF(NOT(ISBLANK(A16)),MONTH(A16),"") -> 1 | X16: =IFERROR(+S16-R16,0) -> 0 | Y16: Diego | AA16: 683 | AC16: =IF(NOT(ISBLANK(K16)),YEAR(K16),"") -> 2024 | AD16: =IF(NOT(ISBLANK(A16)),YEAR(A16),"") -> 2024 | AE16: =IF(NOT(ISBLANK(L16)),YEAR(L16),"") -> 2024 | AF16: =IF(NOT(ISBLANK(L16)),MONTH(L16),"") -> 2
A17: 45316 | B17: 1003 | C17: Ascensores Bariloche | F17: Operador de Puerta | G17: Fermator | H17: VVVF4+ | I17: 11/42739 | K17: 45317 | L17: 45317 | M17: 125 | N17: 105250 | O17: Enviado | P17: Reparado | Q17: Aceptado | R17: =IF(Q17="Aceptado",N17,0) -> 105250 | S17: 105250 | T17: =IFERROR(+T16+R17-S17,0) -> 0 | V17: =IF(NOT(ISBLANK(K17)),MONTH(K17),"") -> 1 | W17: =IF(NOT(ISBLANK(A17)),MONTH(A17),"") -> 1 | X17: =IFERROR(+S17-R17,0) -> 0 | Y17: Diego | AA17: 676 | AC17: =IF(NOT(ISBLANK(K17)),YEAR(K17),"") -> 2024 | AD17: =IF(NOT(ISBLANK(A17)),YEAR(A17),"") -> 2024 | AE17: =IF(NOT(ISBLANK(L17)),YEAR(L17),"") -> 2024 | AF17: =IF(NOT(ISBLANK(L17)),MONTH(L17),"") -> 1
A18: 45317 | B18: 1004 | C18: Julio (Instalador Convertec) | F18: Teclado de música | G18: Casio | H18: CTK-230 | I18: 6369621 | K18: 45322 | L18: 45318 | M18: 100 | N18: 84500 | O18: Enviado | P18: Reparado | Q18: Aceptado | R18: =IF(Q18="Aceptado",N18,0) -> 84500 | S18: 84500 | T18: =IFERROR(+T17+R18-S18,0) -> 0 | V18: =IF(NOT(ISBLANK(K18)),MONTH(K18),"") -> 1 | W18: =IF(NOT(ISBLANK(A18)),MONTH(A18),"") -> 1 | X18: =IFERROR(+S18-R18,0) -> 0 | Y18: Diego | AA18: 675 | AC18: =IF(NOT(ISBLANK(K18)),YEAR(K18),"") -> 2024 | AD18: =IF(NOT(ISBLANK(A18)),YEAR(A18),"") -> 2024 | AE18: =IF(NOT(ISBLANK(L18)),YEAR(L18),"") -> 2024 | AF18: =IF(NOT(ISBLANK(L18)),MONTH(L18),"") -> 1
A19: 45321 | B19: 1005 | C19: Andrés Gallardo (X28) | F19: DVR 8CH | G19: HIKVISION | H19: DS-7208HGHI-SHSE | I19: 496010329 | K19: 45323 | L19: 45323 | M19: 67 | N19: 56800 | O19: Enviado | P19: Reparado | Q19: Aceptado | R19: =IF(Q19="Aceptado",N19,0) -> 56800 | S19: 56800 | T19: =IFERROR(+T18+R19-S19,0) -> 0 | V19: =IF(NOT(ISBLANK(K19)),MONTH(K19),"") -> 2 | W19: =IF(NOT(ISBLANK(A19)),MONTH(A19),"") -> 1 | X19: =IFERROR(+S19-R19,0) -> 0 | Y19: Diego | AA19: 679 | AC19: =IF(NOT(ISBLANK(K19)),YEAR(K19),"") -> 2024 | AD19: =IF(NOT(ISBLANK(A19)),YEAR(A19),"") -> 2024 | AE19: =IF(NOT(ISBLANK(L19)),YEAR(L19),"") -> 2024 | AF19: =IF(NOT(ISBLANK(L19)),MONTH(L19),"") -> 2
A20: 45323 | B20: 1006 | C20: Daniel (Bari Clima) | F20: Placa de caldera | G20: BaxiRoca | H20: Laura 35/35TH | I20: 42,062,03 | K20: 45323 | L20: 45327 | M20: 175 | N20: 147500 | O20: Enviado | P20: Reparado | Q20: Aceptado | R20: =IF(Q20="Aceptado",N20,0) -> 147500 | S20: 147500 | T20: =IFERROR(+T19+R20-S20,0) -> 0 | V20: =IF(NOT(ISBLANK(K20)),MONTH(K20),"") -> 2 | W20: =IF(NOT(ISBLANK(A20)),MONTH(A20),"") -> 2 | X20: =IFERROR(+S20-R20,0) -> 0 | Y20: Diego | AA20: 677 | AC20: =IF(NOT(ISBLANK(K20)),YEAR(K20),"") -> 2024 | AD20: =IF(NOT(ISBLANK(A20)),YEAR(A20),"") -> 2024 | AE20: =IF(NOT(ISBLANK(L20)),YEAR(L20),"") -> 2024 | AF20: =IF(NOT(ISBLANK(L20)),MONTH(L20),"") -> 2
A21: 45323 | B21: 1007 | C21: Daniel (Bari Clima) | F21: Placa de caldera | G21: BaxiRoca | H21: Laura 35/35TH | I21: 42,062,02 | M21: 0 | N21: 0 | O21: BRC | P21: Sin revisar | Q21: A la Espera de Aceptación | R21: =IF(Q21="Aceptado",N21,0) -> 0 | S21: 0 | T21: =IFERROR(+T20+R21-S21,0) -> 0 | V21: =IF(NOT(ISBLANK(K21)),MONTH(K21),"") | W21: =IF(NOT(ISBLANK(A21)),MONTH(A21),"") -> 2 | X21: =IFERROR(+S21-R21,0) -> 0 | AC21: =IF(NOT(ISBLANK(K21)),YEAR(K21),"") | AD21: =IF(NOT(ISBLANK(A21)),YEAR(A21),"") -> 2024 | AE21: =IF(NOT(ISBLANK(L21)),YEAR(L21),"") | AF21: =IF(NOT(ISBLANK(L21)),MONTH(L21),"")
A22: 45324 | B22: 1008 | C22: Asociación Club Los Pehuenes | F22: Detector de Huella | G22: ZKTECO | H22: K20-ID-SSR-V2 | I22: 3157153200136 | K22: 45338 | L22: 45328 | M22: 197.5 | N22: 167500 | O22: Enviado | P22: Reparado | Q22: Aceptado | R22: =IF(Q22="Aceptado",N22,0) -> 167500 | S22: 167500 | T22: =IFERROR(+T21+R22-S22,0) -> 0 | V22: =IF(NOT(ISBLANK(K22)),MONTH(K22),"") -> 2 | W22: =IF(NOT(ISBLANK(A22)),MONTH(A22),"") -> 2 | X22: =IFERROR(+S22-R22,0) -> 0 | Y22: Diego | AA22: 681 | AC22: =IF(NOT(ISBLANK(K22)),YEAR(K22),"") -> 2024 | AD22: =IF(NOT(ISBLANK(A22)),YEAR(A22),"") -> 2024 | AE22: =IF(NOT(ISBLANK(L22)),YEAR(L22),"") -> 2024 | AF22: =IF(NOT(ISBLANK(L22)),MONTH(L22),"") -> 2
A23: 45329 | B23: 1009 | C23: Distribuidora Patagonia | F23: Notebook | G23: Samsung | H23: NP300E5C | I23: BA68-08754A | J23: 5850 | K23: 45329 | L23: 45329 | M23: 70 | N23: 60000 | O23: Enviado | P23: Reparado | Q23: Aceptado | R23: =IF(Q23="Aceptado",N23,0) -> 60000 | S23: 60000 | T23: =IFERROR(+T22+R23-S23,0) -> 0 | V23: =IF(NOT(ISBLANK(K23)),MONTH(K23),"") -> 2 | W23: =IF(NOT(ISBLANK(A23)),MONTH(A23),"") -> 2 | X23: =IFERROR(+S23-R23,0) -> 0 | Y23: Diego | AA23: 678 | AC23: =IF(NOT(ISBLANK(K23)),YEAR(K23),"") -> 2024 | AD23: =IF(NOT(ISBLANK(A23)),YEAR(A23),"") -> 2024 | AE23: =IF(NOT(ISBLANK(L23)),YEAR(L23),"") -> 2024 | AF23: =IF(NOT(ISBLANK(L23)),MONTH(L23),"") -> 2
A24: 45331 | B24: 1010 | C24: Ascensores Lucero | F24: Variador de velocidad 10HP | G24: Telemecanique | H24: ATV31HU75N4 | I24: 8B0931411132 | K24: 45349 | L24: 45334 | M24: 490 | N24: 416500 | O24: Enviado | P24: Reparado | Q24: Aceptado | R24: =IF(Q24="Aceptado",N24,0) -> 416500 | S24: 416500 | T24: =IFERROR(+T23+R24-S24,0) -> 0 | V24: =IF(NOT(ISBLANK(K24)),MONTH(K24),"") -> 2 | W24: =IF(NOT(ISBLANK(A24)),MONTH(A24),"") -> 2 | X24: =IFERROR(+S24-R24,0) -> 0 | Y24: Diego | AA24: 688 | AC24: =IF(NOT(ISBLANK(K24)),YEAR(K24),"") -> 2024 | AD24: =IF(NOT(ISBLANK(A24)),YEAR(A24),"") -> 2024 | AE24: =IF(NOT(ISBLANK(L24)),YEAR(L24),"") -> 2024 | AF24: =IF(NOT(ISBLANK(L24)),MONTH(L24),"") -> 2
A25: 45334 | B25: 1011 | C25: Huilque SRL | F25: Freidora Industrial 8L | G25: Ind. Arg | H25: 8L | I25: IAD5Y | K25: 45335 | L25: 45334 | M25: 90 | N25: 76320 | O25: Enviado | P25: Reparado | Q25: Aceptado | R25: =IF(Q25="Aceptado",N25,0) -> 76320 | S25: 76320 | T25: =IFERROR(+T24+R25-S25,0) -> 0 | V25: =IF(NOT(ISBLANK(K25)),MONTH(K25),"") -> 2 | W25: =IF(NOT(ISBLANK(A25)),MONTH(A25),"") -> 2 | X25: =IFERROR(+S25-R25,0) -> 0 | Y25: Diego | AA25: 680 | AC25: =IF(NOT(ISBLANK(K25)),YEAR(K25),"") -> 2024 | AD25: =IF(NOT(ISBLANK(A25)),YEAR(A25),"") -> 2024 | AE25: =IF(NOT(ISBLANK(L25)),YEAR(L25),"") -> 2024 | AF25: =IF(NOT(ISBLANK(L25)),MONTH(L25),"") -> 2
A26: 45334 | B26: 1012 | C26: Huilque SRL | F26: Freidora Industrial 8L | G26: Ind. Arg. | H26: 8L | I26: E1N6T | K26: 45334 | L26: 45334 | M26: 90 | N26: 76320 | O26: Enviado | P26: Reparado | Q26: Aceptado | R26: =IF(Q26="Aceptado",N26,0) -> 76320 | S26: 76320 | T26: =IFERROR(+T25+R26-S26,0) -> 0 | V26: =IF(NOT(ISBLANK(K26)),MONTH(K26),"") -> 2 | W26: =IF(NOT(ISBLANK(A26)),MONTH(A26),"") -> 2 | X26: =IFERROR(+S26-R26,0) -> 0 | Y26: Diego | AA26: 680 | AC26: =IF(NOT(ISBLANK(K26)),YEAR(K26),"") -> 2024 | AD26: =IF(NOT(ISBLANK(A26)),YEAR(A26),"") -> 2024 | AE26: =IF(NOT(ISBLANK(L26)),YEAR(L26),"") -> 2024 | AF26: =IF(NOT(ISBLANK(L26)),MONTH(L26),"") -> 2
A27: 45335 | B27: 1013 | C27: Distribuidora Patagonia | F27: Impresora | G27: Brother | H27: DCP-T300 | I27: KQSOI | K27: 45335 | L27: 45343 | M27: 135 | N27: 115500 | O27: Enviado | P27: Reparado | Q27: Aceptado | R27: =IF(Q27="Aceptado",N27,0) -> 115500 | S27: 115500 | T27: =IFERROR(+T26+R27-S27,0) -> 0 | V27: =IF(NOT(ISBLANK(K27)),MONTH(K27),"") -> 2 | W27: =IF(NOT(ISBLANK(A27)),MONTH(A27),"") -> 2 | X27: =IFERROR(+S27-R27,0) -> 0 | Y27: Diego | AA27: 684 | AC27: =IF(NOT(ISBLANK(K27)),YEAR(K27),"") -> 2024 | AD27: =IF(NOT(ISBLANK(A27)),YEAR(A27),"") -> 2024 | AE27: =IF(NOT(ISBLANK(L27)),YEAR(L27),"") -> 2024 | AF27: =IF(NOT(ISBLANK(L27)),MONTH(L27),"") -> 2
A28: 45336 | B28: 1014 | C28: IPATEC | F28: Sistema de elaboración de cerveza eléctrico | G28: Robobrew | H28: 008695 | I28: 9337310008695 | K28: 45336 | L28: 45337 | M28: 240 | N28: 240720 | O28: Enviado | P28: Reparado | Q28: Aceptado | R28: =IF(Q28="Aceptado",N28,0) -> 240720 | S28: 240720 | T28: =IFERROR(+T27+R28-S28,0) -> 0 | V28: =IF(NOT(ISBLANK(K28)),MONTH(K28),"") -> 2 | W28: =IF(NOT(ISBLANK(A28)),MONTH(A28),"") -> 2 | X28: =IFERROR(+S28-R28,0) -> 0 | Y28: Diego | AA28: 687 | AC28: =IF(NOT(ISBLANK(K28)),YEAR(K28),"") -> 2024 | AD28: =IF(NOT(ISBLANK(A28)),YEAR(A28),"") -> 2024 | AE28: =IF(NOT(ISBLANK(L28)),YEAR(L28),"") -> 2024 | AF28: =IF(NOT(ISBLANK(L28)),MONTH(L28),"") -> 2
A29: 45343 | B29: 1015 | C29: Hugo | F29: Soldadora inverter 200A | G29: ESAB | H29: LHN 240i Plus | I29: R9KTD | K29: 45345 | L29: 45343 | M29: 280 | N29: 216000 | O29: Enviado | P29: Reparado | Q29: Aceptado | R29: =IF(Q29="Aceptado",N29,0) -> 216000 | S29: 216000 | T29: =IFERROR(+T28+R29-S29,0) -> 0 | V29: =IF(NOT(ISBLANK(K29)),MONTH(K29),"") -> 2 | W29: =IF(NOT(ISBLANK(A29)),MONTH(A29),"") -> 2 | X29: =IFERROR(+S29-R29,0) -> 0 | Y29: Diego | AA29: 686 | AC29: =IF(NOT(ISBLANK(K29)),YEAR(K29),"") -> 2024 | AD29: =IF(NOT(ISBLANK(A29)),YEAR(A29),"") -> 2024 | AE29: =IF(NOT(ISBLANK(L29)),YEAR(L29),"") -> 2024 | AF29: =IF(NOT(ISBLANK(L29)),MONTH(L29),"") -> 2
A30: 45343 | B30: 1016 | C30: Jose Luis (Privatel) | F30: TV LCD 32 | G30: Samsung | H30: LN32B530P7R | I30: AZXT3CPS600005W | K30: 45343 | L30: 45343 | M30: 50 | N30: 43000 | O30: Enviado | P30: Reparado | Q30: Aceptado | R30: =IF(Q30="Aceptado",N30,0) -> 43000 | S30: 43000 | T30: =IFERROR(+T29+R30-S30,0) -> 0 | V30: =IF(NOT(ISBLANK(K30)),MONTH(K30),"") -> 2 | W30: =IF(NOT(ISBLANK(A30)),MONTH(A30),"") -> 2 | X30: =IFERROR(+S30-R30,0) -> 0 | Y30: Diego | AC30: =IF(NOT(ISBLANK(K30)),YEAR(K30),"") -> 2024 | AD30: =IF(NOT(ISBLANK(A30)),YEAR(A30),"") -> 2024 | AE30: =IF(NOT(ISBLANK(L30)),YEAR(L30),"") -> 2024 | AF30: =IF(NOT(ISBLANK(L30)),MONTH(L30),"") -> 2
A31: 45344 | B31: 1017 | C31: Ariel Lotito | F31: Placa de caldera | G31: Ariston | H31: AMPC-GAL1 MCU STD MED FF | I31: 1709066A0178 | K31: 45344 | L31: 45345 | M31: 140 | N31: 110000 | O31: Enviado | P31: Reparado | Q31: Aceptado | R31: =IF(Q31="Aceptado",N31,0) -> 110000 | S31: 110000 | T31: =IFERROR(+T30+R31-S31,0) -> 0 | V31: =IF(NOT(ISBLANK(K31)),MONTH(K31),"") -> 2 | W31: =IF(NOT(ISBLANK(A31)),MONTH(A31),"") -> 2 | X31: =IFERROR(+S31-R31,0) -> 0 | Y31: Diego | AA31: 685 | AC31: =IF(NOT(ISBLANK(K31)),YEAR(K31),"") -> 2024 | AD31: =IF(NOT(ISBLANK(A31)),YEAR(A31),"") -> 2024 | AE31: =IF(NOT(ISBLANK(L31)),YEAR(L31),"") -> 2024 | AF31: =IF(NOT(ISBLANK(L31)),MONTH(L31),"") -> 2
A32: 45344 | B32: 1018 | C32: Distribuidora Patagonia | F32: Impresora Laser | G32: Brother | H32: HL-1212W | I32: U63982F8N692142 | J32: 5942 | K32: 45350 | L32: 45349 | M32: 84 | N32: 72500 | O32: Enviado | P32: Reparado | Q32: Aceptado | R32: =IF(Q32="Aceptado",N32,0) -> 72500 | S32: 72500 | T32: =IFERROR(+T31+R32-S32,0) -> 0 | V32: =IF(NOT(ISBLANK(K32)),MONTH(K32),"") -> 2 | W32: =IF(NOT(ISBLANK(A32)),MONTH(A32),"") -> 2 | X32: =IFERROR(+S32-R32,0) -> 0 | Y32: Diego | AA32: 690 | AC32: =IF(NOT(ISBLANK(K32)),YEAR(K32),"") -> 2024 | AD32: =IF(NOT(ISBLANK(A32)),YEAR(A32),"") -> 2024 | AE32: =IF(NOT(ISBLANK(L32)),YEAR(L32),"") -> 2024 | AF32: =IF(NOT(ISBLANK(L32)),MONTH(L32),"") -> 2
A33: 45348 | B33: 1019 | C33: Alma Del Lago (Almasur S.A.) | F33: Placa de ascensor | G33: Automac | H33: A6220v4 | I33: 199221020 | K33: 45348 | L33: 45349 | M33: 120 | N33: 103000 | O33: Enviado | P33: Reparado | Q33: Aceptado | R33: =IF(Q33="Aceptado",N33,0) -> 103000 | S33: 103000 | T33: =IFERROR(+T32+R33-S33,0) -> 0 | V33: =IF(NOT(ISBLANK(K33)),MONTH(K33),"") -> 2 | W33: =IF(NOT(ISBLANK(A33)),MONTH(A33),"") -> 2 | X33: =IFERROR(+S33-R33,0) -> 0 | Y33: Diego | AA33: 689 | AC33: =IF(NOT(ISBLANK(K33)),YEAR(K33),"") -> 2024 | AD33: =IF(NOT(ISBLANK(A33)),YEAR(A33),"") -> 2024 | AE33: =IF(NOT(ISBLANK(L33)),YEAR(L33),"") -> 2024 | AF33: =IF(NOT(ISBLANK(L33)),MONTH(L33),"") -> 2
A34: 45350.125 | B34: 1020 | C34: Leandro Slosel | F34: Sistema de control de Jacuzzi | G34: Balboa | H34: GL2001M3 | I34: 55216-031106160001 | K34: 45352.125 | L34: 45352.125 | M34: 385 | N34: 331100 | O34: Enviado | P34: Reparado | Q34: Aceptado | R34: =IF(Q34="Aceptado",N34,0) -> 331100 | S34: 331100 | T34: =IFERROR(+T33+R34-S34,0) -> 0 | V34: =IF(NOT(ISBLANK(K34)),MONTH(K34),"") -> 3 | W34: =IF(NOT(ISBLANK(A34)),MONTH(A34),"") -> 2 | X34: =IFERROR(+S34-R34,0) -> 0 | Y34: Diego | AA34: 691 | AC34: =IF(NOT(ISBLANK(K34)),YEAR(K34),"") -> 2024 | AD34: =IF(NOT(ISBLANK(A34)),YEAR(A34),"") -> 2024 | AE34: =IF(NOT(ISBLANK(L34)),YEAR(L34),"") -> 2024 | AF34: =IF(NOT(ISBLANK(L34)),MONTH(L34),"") -> 3
A35: 45352 | B35: 1021 | C35: Julio (Instalador Convertec) | F35: Inverter 12vdc / 220vac - 600W | G35: Enertik | H35: IE-600-12 | I35: E05Q026 | K35: 45352 | M35: 110 | N35: 104000 | O35: BRC | P35: Reparado | Q35: A la Espera de Aceptación | R35: =IF(Q35="Aceptado",N35,0) -> 0 | S35: 0 | T35: =IFERROR(+T34+R35-S35,0) -> 0 | V35: =IF(NOT(ISBLANK(K35)),MONTH(K35),"") -> 3 | W35: =IF(NOT(ISBLANK(A35)),MONTH(A35),"") -> 3 | X35: =IFERROR(+S35-R35,0) -> 0 | Y35: Diego | AC35: =IF(NOT(ISBLANK(K35)),YEAR(K35),"") -> 2024 | AD35: =IF(NOT(ISBLANK(A35)),YEAR(A35),"") -> 2024 | AE35: =IF(NOT(ISBLANK(L35)),YEAR(L35),"") | AF35: =IF(NOT(ISBLANK(L35)),MONTH(L35),"")
A36: 45357 | B36: 1022 | C36: Julio (Instalador Convertec) | F36: Cargador de baterías | G36: Makita | H36: DC18RA | I36: V3C1L | K36: 45357 | L36: 45357 | M36: 52 | N36: 45000 | O36: Enviado | P36: Reparado | Q36: Aceptado | R36: =IF(Q36="Aceptado",N36,0) -> 45000 | S36: 45000 | T36: =IFERROR(+T35+R36-S36,0) -> 0 | V36: =IF(NOT(ISBLANK(K36)),MONTH(K36),"") -> 3 | W36: =IF(NOT(ISBLANK(A36)),MONTH(A36),"") -> 3 | X36: =IFERROR(+S36-R36,0) -> 0 | Y36: Diego | AA36: 692 | AC36: =IF(NOT(ISBLANK(K36)),YEAR(K36),"") -> 2024 | AD36: =IF(NOT(ISBLANK(A36)),YEAR(A36),"") -> 2024 | AE36: =IF(NOT(ISBLANK(L36)),YEAR(L36),"") -> 2024 | AF36: =IF(NOT(ISBLANK(L36)),MONTH(L36),"") -> 3
A37: 45357 | B37: 1023 | C37: Mamuschka SRL | F37: Placa de unidad exterior multisplit | G37: Mitsubishi | H37: INV20Y-BOARD KE76B5INV20Y-BOARD KE76B564G0264G02 | I37: 160112B | K37: 45357 | L37: 45364 | M37: 50 | N37: 49500 | O37: Enviado | P37: Reparado | Q37: Aceptado | R37: =IF(Q37="Aceptado",N37,0) -> 49500 | S37: 49500 | T37: =IFERROR(+T36+R37-S37,0) -> 0 | V37: =IF(NOT(ISBLANK(K37)),MONTH(K37),"") -> 3 | W37: =IF(NOT(ISBLANK(A37)),MONTH(A37),"") -> 3 | X37: =IFERROR(+S37-R37,0) -> 0 | Y37: Diego | AA37: 693 | AC37: =IF(NOT(ISBLANK(K37)),YEAR(K37),"") -> 2024 | AD37: =IF(NOT(ISBLANK(A37)),YEAR(A37),"") -> 2024 | AE37: =IF(NOT(ISBLANK(L37)),YEAR(L37),"") -> 2024 | AF37: =IF(NOT(ISBLANK(L37)),MONTH(L37),"") -> 3
A38: 45362 | B38: 1024 | C38: Abuelo Ian | F38: Motor de portón eléctrico | G38: Central Tem | H38: PCI 0106/2 | I38: K371U | K38: 45362 | L38: 45362 | M38: 63 | N38: 55000 | O38: Enviado | P38: Reparado | Q38: Aceptado | R38: =IF(Q38="Aceptado",N38,0) -> 55000 | S38: 55000 | T38: =IFERROR(+T37+R38-S38,0) -> 0 | V38: =IF(NOT(ISBLANK(K38)),MONTH(K38),"") -> 3 | W38: =IF(NOT(ISBLANK(A38)),MONTH(A38),"") -> 3 | X38: =IFERROR(+S38-R38,0) -> 0 | Y38: Diego | AC38: =IF(NOT(ISBLANK(K38)),YEAR(K38),"") -> 2024 | AD38: =IF(NOT(ISBLANK(A38)),YEAR(A38),"") -> 2024 | AE38: =IF(NOT(ISBLANK(L38)),YEAR(L38),"") -> 2024 | AF38: =IF(NOT(ISBLANK(L38)),MONTH(L38),"") -> 3
A39: 45363 | B39: 1025 | C39: Nicolás (Placas Lav_Sec ropas) | F39: Placa de Lavarropas Next Eco | G39: Drean | H39: 772204100 | I39: 3009162 | K39: 45363 | L39: 45366 | M39: 61 | N39: 53000 | O39: BRC | P39: Reparado | Q39: Aceptado | R39: =IF(Q39="Aceptado",N39,0) -> 53000 | S39: 53000 | T39: =IFERROR(+T38+R39-S39,0) -> 0 | V39: =IF(NOT(ISBLANK(K39)),MONTH(K39),"") -> 3 | W39: =IF(NOT(ISBLANK(A39)),MONTH(A39),"") -> 3 | X39: =IFERROR(+S39-R39,0) -> 0 | Y39: Diego | AA39: 694 | AC39: =IF(NOT(ISBLANK(K39)),YEAR(K39),"") -> 2024 | AD39: =IF(NOT(ISBLANK(A39)),YEAR(A39),"") -> 2024 | AE39: =IF(NOT(ISBLANK(L39)),YEAR(L39),"") -> 2024 | AF39: =IF(NOT(ISBLANK(L39)),MONTH(L39),"") -> 3
A40: 45363 | B40: 1026 | C40: Nicolás (Placas Lav_Sec ropas) | F40: Placa de Secarropas ASL70C | G40: Ariston | H40: LT C126 | I40: 0639 | K40: 45363 | L40: 45366 | M40: 127 | N40: 110000 | O40: BRC | P40: Reparado | Q40: Aceptado | R40: =IF(Q40="Aceptado",N40,0) -> 110000 | S40: 110000 | T40: =IFERROR(+T39+R40-S40,0) -> 0 | V40: =IF(NOT(ISBLANK(K40)),MONTH(K40),"") -> 3 | W40: =IF(NOT(ISBLANK(A40)),MONTH(A40),"") -> 3 | X40: =IFERROR(+S40-R40,0) -> 0 | Y40: Diego | AA40: 694 | AC40: =IF(NOT(ISBLANK(K40)),YEAR(K40),"") -> 2024 | AD40: =IF(NOT(ISBLANK(A40)),YEAR(A40),"") -> 2024 | AE40: =IF(NOT(ISBLANK(L40)),YEAR(L40),"") -> 2024 | AF40: =IF(NOT(ISBLANK(L40)),MONTH(L40),"") -> 3
...

Sheet Costos Fijos
A1: 2024 | B1: Diego | C1: Laura | D1: Sergio | E1: Camuzzi GAS + Agua | F1: Luz Onelli | G1: Internet | H1: Monotributo + IIBB | I1: Alquiler+exp+Muni | K1: Gastos Var | L1: Total
A2: Enero | B2: 700000 | D2: 700000 | E2: =[1]Enero!$D$8+[1]Enero!$D$10 -> 3400 | F2: =[1]Enero!$D$5 -> 4100 | G2: =[2]Enero!$D$6 -> 0 | H2: 42052.97 | I2: =[1]Enero!$D$7+ [1]Enero!$D$9 -> 1300 | K2: =[1]Enero!$C$58 -> 13729.76 | L2: =SUM(B2:K2) -> 1464582.7
A3: Febrero | B3: 770000 | D3: 770000 | E3: =[1]Febrero!$D$8+[1]Febrero!$D$10 -> 3400 | F3: =[1]Febrero!$D$5 -> 6500 | G3: =[2]Febrero!$D$6 -> 0 | H3: 52019.61 | I3: =[1]Febrero!$D$7+ [1]Febrero!$D$9 -> 218540 | K3: =[1]Febrero!$C$58 -> 162908.07 | L3: =SUM(B3:K3) -> 1983367.7
A4: Marzo | B4: 770000 | D4: 770000 | E4: =[1]Marzo!$D$8+[1]Marzo!$D$10 -> 4200 | F4: =[1]Marzo!$D$5 -> 6500 | G4: =[2]Marzo!$D$6 -> 0 | H4: 52019.61 | I4: =[1]Marzo!$D$7+ [1]Marzo!$D$9 -> 257410 | K4: =[1]Marzo!$C$58 -> 69024.19 | L4: =SUM(B4:K4) -> 1929153.8
A5: Abril | B5: 770000 | D5: 770000 | E5: =[1]Abril!$D$8+[1]Abril!$D$10 -> 4200 | F5: =[1]Abril!$D$5 -> 12350 | G5: =[2]Abril!$D$6 -> 0 | H5: 52019.61 | I5: =[1]Abril!$D$7+ [1]Abril!$D$9 -> 303300 | K5: =[1]Abril!$C$58 -> 31252.73 | L5: =SUM(B5:K5) -> 1943122.3
A6: Mayo | B6: 770000 | D6: 770000 | E6: =[1]Mayo!$D$8+[1]Mayo!$D$10 -> 6300 | F6: =[1]Mayo!$D$5 -> 13215 | G6: =[2]Mayo!$D$6 -> 0 | H6: 52019.61 | I6: =[1]Mayo!$D$7 + [1]Mayo!$D$9 -> 333340 | K6: =[1]Mayo!$C$60 -> 309378.47 | L6: =SUM(B6:K6) -> 2254253.1
A7: Junio | B7: 900000 | D7: 900000 | E7: =[1]Junio!$D$8+[1]Junio!$D$10 -> 6300 | F7: =[1]Junio!$D$5 -> 15000 | G7: =[2]Junio!$D$6 -> 0 | H7: 52019.61 | I7: =[1]Junio!$D$7+ [1]Junio!$D$9 -> 366410 | K7: =[1]Junio!$C$58 -> 195581.23 | L7: =SUM(B7:K7) -> 2435310.8
A8: Julio | B8: 900000 | D8: 900000 | E8: =[1]Julio!$D$8+[1]Julio!$D$10 -> 18100 | F8: =[1]Julio!$D$5 -> 25000 | G8: =[2]Julio!$D$6 -> 0 | H8: 52019.61 | I8: =[1]Julio!$D$7+ [1]Julio!$D$9 -> 402800 | K8: =[1]Julio!$C$58 -> 169177.97 | L8: =SUM(B8:K8) -> 2467097.6
A9: Agosto | B9: 1200000 | D9: 1200000 | E9: =[1]Agosto!$D$8+[1]Agosto!$D$10 -> 18100 | F9: =[1]Agosto!$D$5 -> 27500 | G9: =[2]Agosto!$D$6 -> 0 | H9: 56764.58 | I9: =[1]Agosto!$D$7+ [1]Agosto!$D$9 -> 402800 | K9: =[1]Agosto!$C$58 -> 593043 | L9: =SUM(B9:K9) -> 3498207.6
A10: Septiembre | B10: 1200000 | D10: 1200000 | E10: =[1]Septiembre!$D$8+[1]Septiembre!$D$10 -> 21400 | F10: =[1]Septiembre!$D$5 -> 33000 | G10: =[1]Septiembre!$D$6 -> 0 | H10: 56764.58 | I10: =[1]Septiembre!$D$7 + [1]Septiembre!$D$9 -> 402800 | K10: =[1]Septiembre!$C$58 -> 353258.95 | L10: =SUM(B10:K10) -> 3267223.5
A11: Octubre | B11: 1200000 | D11: 1200000 | E11: =[1]Octubre!$D$8+[1]Octubre!$D$10 -> 21400 | F11: =[1]Octubre!$D$5 -> 33000 | G11: =[1]Octubre!$D$6 -> 12000 | H11: 56764.58 | I11: =[1]Octubre!$D$7 + [1]Octubre!$D$9 -> 402800 | K11: =[1]Octubre!$C$58 -> 304092.08 | L11: =SUM(B11:K11) -> 3230056.7
A12: Noviembre | B12: 1200000 | D12: 1200000 | E12: =[1]Noviembre!$D$8+[1]Noviembre!$D$10 -> 22400 | F12: =[1]Noviembre!$D$5 -> 33000 | G12: =[1]Noviembre!$D$6 -> 12000 | H12: 56764.58 | I12: =[1]Noviembre!$D$7 + [1]Noviembre!$D$9 -> 414806 | K12: =[1]Noviembre!$C$58 -> 264846.26 | L12: =SUM(B12:K12) -> 3203816.8
A13: Diciembre | B13: 1500000 | D13: 154307 | E13: =[1]Diciembre!$D$8+[1]Diciembre!$D$10 -> 22400 | F13: =[1]Diciembre!$D$5 -> 35000 | G13: =[1]Diciembre!$D$6 -> 12000 | H13: 56764.58 | I13: =[1]Diciembre!$D$7 + [1]Diciembre!$D$9 -> 864470 | K13: =[1]Diciembre!$C$58 -> 55572.73 | L13: =SUM(B13:K13) -> 2700514.3
A14: ANUAL | B14: =SUM(B2:B13) -> 11880000 | C14: =SUM(C2:C13) -> 0 | D14: =SUM(D2:D13) -> 10534307 | E14: =SUM(E2:E13) -> 151600 | F14: =SUM(F2:F13) -> 244165 | G14: =SUM(G2:G13) -> 36000 | H14: =SUM(H2:H13) -> 637993.53 | I14: =SUM(I2:I13) -> 4370776 | ... L14: =SUM(L2:L13) -> 30376707
A18: 2025 | B18: Diego | C18: Laura | D18: Sergio | E18: Camuzzi GAS + Agua | F18: Luz Onelli | G18: Internet | H18: Monotributo + IIBB | I18: Alquiler+exp+Muni | K18: Gastos Var | L18: Total
A19: Enero | B19: 1500000 | E19: =[3]Enero!$D$8+[3]Enero!$D$10 -> 22900 | F19: =[3]Enero!$D$5 -> 36000 | G19: =[3]Enero!$D$6 -> 13500 | H19: 56764.58 | I19: =[3]Enero!$D$7+ [3]Enero!$D$9 -> 2600 | K19: =[3]Enero!$C$58 -> 325599.2 | L19: =SUM(B19:K19) -> 1957363.8
A20: Febrero | B20: 1500000 | E20: =[3]Febrero!$D$8+[3]Febrero!$D$10 -> 22900 | F20: =[3]Febrero!$D$5 -> 36000 | G20: =[3]Febrero!$D$6 -> 13500 | H20: 95327.59 | I20: =[3]Febrero!$D$7+ [3]Febrero!$D$9 -> 449000 | K20: =[3]Febrero!$C$58 -> 79883.81 | L20: =SUM(B20:K20) -> 2196611.4
A21: Marzo | B21: 1500000 | E21: =[3]Marzo!$D$8+[3]Marzo!$D$10 -> 19400 | F21: =[3]Marzo!$D$5 -> 39500 | G21: =[3]Marzo!$D$6 -> 13500 | H21: 95327.59 | I21: =[3]Marzo!$D$7+ [3]Marzo!$D$9 -> 456000 | K21: =[3]Marzo!$C$58 -> 84314.89 | L21: =SUM(B21:K21) -> 2208042.5
A22: Abril | E22: =[3]Abril!$D$8+[3]Abril!$D$10 -> 19400 | F22: =[3]Abril!$D$5 -> 39500 | G22: =[3]Abril!$D$6 -> 14800 | H22: 95327.59 | I22: =[3]Abril!$D$7+ [3]Abril!$D$9 -> 463000 | K22: =[3]Abril!$C$58 -> 188286.97 | L22: =SUM(B22:K22) -> 820314.56
A23: Mayo | E23: =[3]Mayo!$D$8+[3]Mayo!$D$10 -> 0 | F23: =[3]Mayo!$D$5 -> 0 | G23: =[3]Mayo!$D$6 -> 0 | I23: =[3]Mayo!$D$7 + [3]Mayo!$D$9 -> 0 | K23: =[3]Mayo!$C$60 -> 0 | L23: =SUM(B23:K23) -> 0
A24: Junio | E24: =[3]Junio!$D$8+[3]Junio!$D$10 -> 0 | F24: =[3]Junio!$D$5 -> 0 | G24: =[3]Junio!$D$6 -> 0 | I24: =[3]Junio!$D$7+ [3]Junio!$D$9 -> 0 | K24: =[3]Junio!$C$58 -> 0 | L24: =SUM(B24:K24) -> 0
A25: Julio | E25: =[3]Julio!$D$8+[3]Julio!$D$10 -> 0 | F25: =[3]Julio!$D$5 -> 0 | G25: =[3]Julio!$D$6 -> 0 | I25: =[3]Julio!$D$7+ [3]Julio!$D$9 -> 0 | K25: =[3]Julio!$C$58 -> 0 | L25: =SUM(B25:K25) -> 0
A26: Agosto | E26: =[3]Agosto!$D$8+[3]Agosto!$D$10 -> 0 | F26: =[3]Agosto!$D$5 -> 0 | G26: =[3]Agosto!$D$6 -> 0 | I26: =[3]Agosto!$D$7+ [3]Agosto!$D$9 -> 0 | K26: =[3]Agosto!$C$58 -> 0 | L26: =SUM(B26:K26) -> 0
A27: Septiembre | E27: =[3]Septiembre!$D$8+[3]Septiembre!$D$10 -> 0 | F27: =[3]Septiembre!$D$5 -> 0 | G27: =[3]Septiembre!$D$6 -> 0 | I27: =[3]Septiembre!$D$7 + [3]Septiembre!$D$9 -> 0 | K27: =[3]Septiembre!$C$58 -> 0 | L27: =SUM(B27:K27) -> 0
A28: Octubre | E28: =[3]Octubre!$D$8+[3]Octubre!$D$10 -> 0 | F28: =[3]Octubre!$D$5 -> 0 | G28: =[3]Octubre!$D$6 -> 0 | I28: =[3]Octubre!$D$7 + [3]Octubre!$D$9 -> 0 | K28: =[3]Octubre!$C$58 -> 0 | L28: =SUM(B28:K28) -> 0
A29: Noviembre | E29: =[3]Noviembre!$D$8+[3]Noviembre!$D$10 -> 0 | F29: =[3]Noviembre!$D$5 -> 0 | G29: =[3]Noviembre!$D$6 -> 0 | I29: =[3]Noviembre!$D$7 + [3]Noviembre!$D$9 -> 0 | K29: =[3]Noviembre!$C$58 -> 0 | L29: =SUM(B29:K29) -> 0
A30: Diciembre | E30: =[3]Diciembre!$D$8+[3]Diciembre!$D$10 -> 0 | F30: =[3]Diciembre!$D$5 -> 0 | G30: =[3]Diciembre!$D$6 -> 0 | I30: =[3]Diciembre!$D$7 + [3]Diciembre!$D$9 -> 0 | K30: =[3]Diciembre!$C$58 -> 0 | L30: =SUM(B30:K30) -> 0
A31: ANUAL | B31: =SUM(B19:B30) -> 4500000 | C31: =SUM(C19:C30) -> 0 | D31: =SUM(D19:D30) -> 0 | E31: =SUM(E19:E30) -> 84600 | F31: =SUM(F19:F30) -> 151000 | G31: =SUM(G19:G30) -> 55300 | H31: =SUM(H19:H30) -> 342747.35 | I31: =SUM(I19:I30) -> 1370600 | ... L31: =SUM(L19:L30) -> 7182332.2

Sheet Resumen
A1: 2024 | B1: Facturacion | C1: Ganacia neta | D1: % costos fijos | E1: Cant Rep | F1: Cant Ent | G1: Dif GB-Fact | H1: Ganancia ELS | I1: Utilidad neta | J1: A COBRAR | K1: INVERTIDO | L1: INGRESO POR INVERSIÓN | M1: DÓLARES | O1: CAJA AÑO ANTERIOR | P1: -104012
A2: Enero | B2: =SUMIFS(Ordenes!R$2:R$1275,Ordenes!AF$2:AF$1275,MONTH(A2 &1),Ordenes!AE$2:AE$1275,A$1) -> 874050 | C2: =+B2-'Costos Fijos'!L2 -> -590532.73 | D2: =IFERROR(1-(C2/B2),"") -> 1.6756281 | E2: =COUNTIFS(Ordenes!V:V,MONTH(A2 &1),Ordenes!AC:AC,A$1) -> 16 | F2: =COUNTIFS(Ordenes!W:W,MONTH(A2 &1),Ordenes!AD:AD,A$1) -> 18 | G2: =B2-C2 -> 1464582.7 | H2: =+C2 -> -590532.73 | I2: =IFERROR(+H2/B2,"") -> -0.67562809 | J2: =-SUMIFS(Ordenes!X$2:X$1275,Ordenes!AF$2:AF$1275,MONTH(A2 &1),Ordenes!AE$2:AE$1275,A$1) -> 0 | L2: =891130+83253.6 -> 974383.6
A3: Febrero | B3: =SUMIFS(Ordenes!R$2:R$1275,Ordenes!AF$2:AF$1275,MONTH(A3 &1),Ordenes!AE$2:AE$1275,A$1) -> 3505517 | C3: =+B3-'Costos Fijos'!L3 -> 1522149.3 | D3: =IFERROR(1-(C3/B3),"") -> 0.56578464 | E3: =COUNTIFS(Ordenes!V:V,MONTH(A3 &1),Ordenes!AC:AC,A$1) -> 15 | F3: =COUNTIFS(Ordenes!W:W,MONTH(A3 &1),Ordenes!AD:AD,A$1) -> 15 | G3: =B3-C3 -> 1983367.7 | H3: =+C3 -> 1522149.3 | I3: =IFERROR(+H3/B3,"") -> 0.43421536 | J3: =-SUMIFS(Ordenes!X$2:X$1275,Ordenes!AF$2:AF$1275,MONTH(A3 &1),Ordenes!AE$2:AE$1275,A$1) -> 0 | K3: =800000+1000000+310500 -> 2110500 | L3: =680594.32+61533.19+459512+41544.96 -> 1243184.5 | M3: 300
A4: Marzo | B4: =SUMIFS(Ordenes!R$2:R$1275,Ordenes!AF$2:AF$1275,MONTH(A4 &1),Ordenes!AE$2:AE$1275,A$1) -> 1307235 | C4: =+B4-'Costos Fijos'!L4 -> -621918.8 | D4: =IFERROR(1-(C4/B4),"") -> 1.4757513 | E4: =COUNTIFS(Ordenes!V:V,MONTH(A4 &1),Ordenes!AC:AC,A$1) -> 15 | F4: =COUNTIFS(Ordenes!W:W,MONTH(A4 &1),Ordenes!AD:AD,A$1) -> 15 | G4: =B4-C4 -> 1929153.8 | H4: =+C4 -> -621918.8 | I4: =IFERROR(+H4/B4,"") -> -0.47575134 | J4: =-SUMIFS(Ordenes!X$2:X$1275,Ordenes!AF$2:AF$1275,MONTH(A4 &1),Ordenes!AE$2:AE$1275,A$1) -> 0 | L4: =847344.52+153218.46+988365.6+178718.16 -> 2167646.7
A5: Abril | B5: =SUMIFS(Ordenes!R$2:R$1275,Ordenes!AF$2:AF$1275,MONTH(A5 &1),Ordenes!AE$2:AE$1275,A$1) -> 1606700 | C5: =+B5-'Costos Fijos'!L5 -> -336422.34 | D5: =IFERROR(1-(C5/B5),"") -> 1.2093872 | E5: =COUNTIFS(Ordenes!V:V,MONTH(A5 &1),Ordenes!AC:AC,A$1) -> 12 | F5: =COUNTIFS(Ordenes!W:W,MONTH(A5 &1),Ordenes!AD:AD,A$1) -> 12 | G5: =B5-C5 -> 1943122.3 | H5: =+C5 -> -336422.34 | I5: =IFERROR(+H5/B5,"") -> -0.20938715 | J5: =-SUMIFS(Ordenes!X$2:X$1275,Ordenes!AF$2:AF$1275,MONTH(A5 &1),Ordenes!AE$2:AE$1275,A$1) -> 0 | K5: =1500000+1000000+1008557.89 -> 3508557.9 | L5: =405193.19 +112343.97+190.61+1500000+86301 -> 2104028.8
A6: Mayo | B6: =SUMIFS(Ordenes!R$2:R$1275,Ordenes!AF$2:AF$1275,MONTH(A6 &1),Ordenes!AE$2:AE$1275,A$1) -> 3641029 | C6: =+B6-'Costos Fijos'!L6 -> 1386775.9 | D6: =IFERROR(1-(C6/B6),"") -> 0.61912527 | E6: =COUNTIFS(Ordenes!V:V,MONTH(A6 &1),Ordenes!AC:AC,A$1) -> 23 | F6: =COUNTIFS(Ordenes!W:W,MONTH(A6 &1),Ordenes!AD:AD,A$1) -> 24 | G6: =B6-C6 -> 2254253.1 | H6: =+C6 -> 1386775.9 | I6: =IFERROR(+H6/B6,"") -> 0.38087473 | J6: =-SUMIFS(Ordenes!X$2:X$1275,Ordenes!AF$2:AF$1275,MONTH(A6 &1),Ordenes!AE$2:AE$1275,A$1) -> 0 | K6: 520000 | M6: 500
A7: Junio | B7: =SUMIFS(Ordenes!R$2:R$1275,Ordenes!AF$2:AF$1275,MONTH(A7 &1),Ordenes!AE$2:AE$1275,A$1) -> 3587405 | C7: =+B7-'Costos Fijos'!L7 -> 1152094.2 | D7: =IFERROR(1-(C7/B7),"") -> 0.67885027 | E7: =COUNTIFS(Ordenes!V:V,MONTH(A7 &1),Ordenes!AC:AC,A$1) -> 19 | F7: =COUNTIFS(Ordenes!W:W,MONTH(A7 &1),Ordenes!AD:AD,A$1) -> 21 | G7: =B7-C7 -> 2435310.8 | H7: =+C7 -> 1152094.2 | I7: =IFERROR(+H7/B7,"") -> 0.32114973 | J7: =-SUMIFS(Ordenes!X$2:X$1275,Ordenes!AF$2:AF$1275,MONTH(A7 &1),Ordenes!AE$2:AE$1275,A$1) -> 15000 | K7: 1512789.6
A8: Julio | B8: =SUMIFS(Ordenes!R$2:R$1275,Ordenes!AF$2:AF$1275,MONTH(A8 &1),Ordenes!AE$2:AE$1275,A$1) -> 3048355 | C8: =+B8-'Costos Fijos'!L8 -> 581257.42 | D8: =IFERROR(1-(C8/B8),"") -> 0.80932096 | E8: =COUNTIFS(Ordenes!V:V,MONTH(A8 &1),Ordenes!AC:AC,A$1) -> 16 | F8: =COUNTIFS(Ordenes!W:W,MONTH(A8 &1),Ordenes!AD:AD,A$1) -> 20 | G8: =B8-C8 -> 2467097.6 | H8: =+C8 -> 581257.42 | I8: =IFERROR(+H8/B8,"") -> 0.19067904 | J8: =-SUMIFS(Ordenes!X$2:X$1275,Ordenes!AF$2:AF$1275,MONTH(A8 &1),Ordenes!AE$2:AE$1275,A$1) -> 0
A9: Agosto | B9: =SUMIFS(Ordenes!R$2:R$1275,Ordenes!AF$2:AF$1275,MONTH(A9 &1),Ordenes!AE$2:AE$1275,A$1) -> 4608450 | C9: =+B9-'Costos Fijos'!L9 -> 1110242.4 | D9: =IFERROR(1-(C9/B9),"") -> 0.7590855 | E9: =COUNTIFS(Ordenes!V:V,MONTH(A9 &1),Ordenes!AC:AC,A$1) -> 14 | F9: =COUNTIFS(Ordenes!W:W,MONTH(A9 &1),Ordenes!AD:AD,A$1) -> 9 | G9: =B9-C9 -> 3498207.6 | H9: =+C9 -> 1110242.4 | I9: =IFERROR(+H9/B9,"") -> 0.2409145 | J9: =-SUMIFS(Ordenes!X$2:X$1275,Ordenes!AF$2:AF$1275,MONTH(A9 &1),Ordenes!AE$2:AE$1275,A$1) -> 0 | K9: =1614344.15+408000 -> 2022344.1 | M9: 300
A10: Septiembre | B10: =SUMIFS(Ordenes!R$2:R$1275,Ordenes!AF$2:AF$1275,MONTH(A10 &1),Ordenes!AE$2:AE$1275,A$1)+20000 -> 4334881 | C10: =+B10-'Costos Fijos'!L10 -> 1067657.5 | D10: =IFERROR(1-(C10/B10),"") -> 0.75370547 | E10: =COUNTIFS(Ordenes!V:V,MONTH(A10 &1),Ordenes!AC:AC,A$1) -> 23 | F10: =COUNTIFS(Ordenes!W:W,MONTH(A10 &1),Ordenes!AD:AD,A$1) -> 25 | G10: =B10-C10 -> 3267223.5 | H10: =+C10 -> 1067657.5 | I10: =IFERROR(+H10/B10,"") -> 0.24629453 | J10: =-SUMIFS(Ordenes!X$2:X$1275,Ordenes!AF$2:AF$1275,MONTH(A10 &1),Ordenes!AE$2:AE$1275,A$1) -> 0
A11: Octubre | B11: =SUMIFS(Ordenes!R$2:R$1275,Ordenes!AF$2:AF$1275,MONTH(A11 &1),Ordenes!AE$2:AE$1275,A$1) -> 2852200 | C11: =+B11-'Costos Fijos'!L11 -> -377856.66 | D11: =IFERROR(1-(C11/B11),"") -> 1.132479 | E11: =COUNTIFS(Ordenes!V:V,MONTH(A11 &1),Ordenes!AC:AC,A$1) -> 16 | F11: =COUNTIFS(Ordenes!W:W,MONTH(A11 &1),Ordenes!AD:AD,A$1) -> 14 | G11: =B11-C11 -> 3230056.7 | H11: =+C11 -> -377856.66 | I11: =IFERROR(+H11/B11,"") -> -0.13247902 | J11: =-SUMIFS(Ordenes!X$2:X$1275,Ordenes!AF$2:AF$1275,MONTH(A11 &1),Ordenes!AE$2:AE$1275,A$1) -> 0 | K11: =367500+610000+1714771.39 -> 2692271.4 | M11: =300+500 -> 800 | P11: =P1+H14-J14 -> 4793863
A12: Noviembre | B12: =SUMIFS(Ordenes!R$2:R$1275,Ordenes!AF$2:AF$1275,MONTH(A12 &1),Ordenes!AE$2:AE$1275,A$1) -> 3754660 | C12: =+B12-'Costos Fijos'!L12 -> 550843.16 | D12: =IFERROR(1-(C12/B12),"") -> 0.8532908 | E12: =COUNTIFS(Ordenes!V:V,MONTH(A12 &1),Ordenes!AC:AC,A$1) -> 20 | F12: =COUNTIFS(Ordenes!W:W,MONTH(A12 &1),Ordenes!AD:AD,A$1) -> 22 | G12: =B12-C12 -> 3203816.8 | H12: =+C12 -> 550843.16 | I12: =IFERROR(+H12/B12,"") -> 0.1467092 | J12: =-SUMIFS(Ordenes!X$2:X$1275,Ordenes!AF$2:AF$1275,MONTH(A12 &1),Ordenes!AE$2:AE$1275,A$1) -> 0 | M12: 1450.03 | O12: EQUIPOS 2023 COBRADOS EN 2024
A13: Diciembre | B13: =SUMIFS(Ordenes!R$2:R$1275,Ordenes!AF$2:AF$1275,MONTH(A13 &1),Ordenes!AE$2:AE$1275,A$1) -> 2169100 | C13: =+B13-'Costos Fijos'!L13 -> -531414.31 | D13: =IFERROR(1-(C13/B13),"") -> 1.244993 | E13: =COUNTIFS(Ordenes!V:V,MONTH(A13 &1),Ordenes!AC:AC,A$1) -> 12 | F13: =COUNTIFS(Ordenes!W:W,MONTH(A13 &1),Ordenes!AD:AD,A$1) -> 12 | G13: =B13-C13 -> 2700514.3 | H13: =+C13 -> -531414.31 | I13: =IFERROR(+H13/B13,"") -> -0.244993 | J13: =-SUMIFS(Ordenes!X$2:X$1275,Ordenes!AF$2:AF$1275,MONTH(A13 &1),Ordenes!AE$2:AE$1275,A$1) -> 0 | K13: 602500 | M13: 500 | O13: TOTAL REAL EN CAJA | P13: =P11+P12+L14-K14 -> -1685856.5
A14: ANUAL | B14: =SUM(B2:B13) -> 35289582 | C14: =SUM(C2:C13) -> 4912875 | D14: =IFERROR(1-(C14/B14),"") -> 0.86078398 | E14: =SUM(E2:E13) -> 201 | F14: =SUM(F2:F13) -> 207 | G14: =B14-C14 -> 30376707 | H14: =+C14 -> 4912875 | I14: =IFERROR(+H14/B14,"") -> 0.13921602 | J14: =SUM(J2:J13) -> 15000 | K14: =SUM(K2:K13) -> 12968963 | L14: =SUM(L2:L13) -> 6489243.6 | M14: =SUM(M2:M13)+2239 -> 6089.03 | O14: DIEFERENCIA CON CAJA BRC | P14: =P13-'[4]2024'!$P$500 -> 0.49
A17: 2025 | B17: Facturacion | C17: Ganacia neta | D17: % costos fijos | E17: Cant Rep | F17: Cant Ent | G17: Dif GB-Fact | H17: Ganancia ELS | I17: Utilidad neta | J17: A COBRAR | K17: INVERTIDO | L17: INGRESO POR INVERSIÓN | M17: DÓLARES
A18: Enero | B18: =SUMIFS(Ordenes!R$2:R$1275,Ordenes!AF$2:AF$1275,MONTH(A18 &1),Ordenes!AE$2:AE$1275,A$17) -> 3238880 | C18: =+B18-'Costos Fijos'!L19 -> 1281516.2 | D18: =IFERROR(1-(C18/B18),"") -> 0.60433353 | E18: =COUNTIFS(Ordenes!V:V,MONTH(A18 &17),Ordenes!AC:AC,A$17) -> 20 | F18: =COUNTIFS(Ordenes!W:W,MONTH(A18 &17),Ordenes!AD:AD,A$17) -> 23 | G18: =B18-C18 -> 1957363.8 | H18: =+C18 -> 1281516.2 | I18: =IFERROR(+H18/B18,"") -> 0.39566647 | J18: =-SUMIFS(Ordenes!X$2:X$1275,Ordenes!AF$2:AF$1275,MONTH(A18 &17),Ordenes!AE$2:AE$1275,A$17) -> 0 | L18: 400661.78
A19: Febrero | B19: =SUMIFS(Ordenes!R$2:R$1275,Ordenes!AF$2:AF$1275,MONTH(A19 &1),Ordenes!AE$2:AE$1275,A$17) -> 4778900 | C19: =+B19-'Costos Fijos'!L20 -> 2582288.6 | D19: =IFERROR(1-(C19/B19),"") -> 0.45964791 | E19: =COUNTIFS(Ordenes!V:V,MONTH(A19 &17),Ordenes!AC:AC,A$17) -> 22 | F19: =COUNTIFS(Ordenes!W:W,MONTH(A19 &17),Ordenes!AD:AD,A$17) -> 21 | G19: =B19-C19 -> 2196611.4 | H19: =+C19 -> 2582288.6 | I19: =IFERROR(+H19/B19,"") -> 0.54035209 | J19: =-SUMIFS(Ordenes!X$2:X$1275,Ordenes!AF$2:AF$1275,MONTH(A19 &17),Ordenes!AE$2:AE$1275,A$17) -> 0 | L19: 702120.45
A20: Marzo | B20: =SUMIFS(Ordenes!R$2:R$1275,Ordenes!AF$2:AF$1275,MONTH(A20 &1),Ordenes!AE$2:AE$1275,A$17) -> 3145000 | C20: =+B20-'Costos Fijos'!L21 -> 936957.52 | D20: =IFERROR(1-(C20/B20),"") -> 0.70208028 | E20: =COUNTIFS(Ordenes!V:V,MONTH(A20 &17),Ordenes!AC:AC,A$17) -> 20 | F20: =COUNTIFS(Ordenes!W:W,MONTH(A20 &17),Ordenes!AD:AD,A$17) -> 16 | G20: =B20-C20 -> 2208042.5 | H20: =+C20 -> 936957.52 | I20: =IFERROR(+H20/B20,"") -> 0.29791972 | J20: =-SUMIFS(Ordenes!X$2:X$1275,Ordenes!AF$2:AF$1275,MONTH(A20 &17),Ordenes!AE$2:AE$1275,A$17) -> 109500 | L20: 799548.96
A21: Abril | B21: =SUMIFS(Ordenes!R$2:R$1275,Ordenes!AF$2:AF$1275,MONTH(A21 &1),Ordenes!AE$2:AE$1275,A$17) -> 5408100 | C21: =+B21-'Costos Fijos'!L22 -> 4587785.4 | D21: =IFERROR(1-(C21/B21),"") -> 0.15168258 | E21: =COUNTIFS(Ordenes!V:V,MONTH(A21 &17),Ordenes!AC:AC,A$17) -> 24 | F21: =COUNTIFS(Ordenes!W:W,MONTH(A21 &17),Ordenes!AD:AD,A$17) -> 21 | G21: =B21-C21 -> 820314.56 | H21: =+C21 -> 4587785.4 | I21: =IFERROR(+H21/B21,"") -> 0.84831742 | J21: =-SUMIFS(Ordenes!X$2:X$1275,Ordenes!AF$2:AF$1275,MONTH(A21 &17),Ordenes!AE$2:AE$1275,A$17) -> 2737100 | K21: 1250000 | L21: 708435.94 | M21: 1000
A22: Mayo | B22: =SUMIFS(Ordenes!R$2:R$1275,Ordenes!AF$2:AF$1275,MONTH(A22 &1),Ordenes!AE$2:AE$1275,A$17) -> 0 | C22: =+B22-'Costos Fijos'!L23 -> 0 | D22: =IFERROR(1-(C22/B22),"") | E22: =COUNTIFS(Ordenes!V:V,MONTH(A22 &17),Ordenes!AC:AC,A$17) -> 0 | F22: =COUNTIFS(Ordenes!W:W,MONTH(A22 &17),Ordenes!AD:AD,A$17) -> 0 | G22: =B22-C22 -> 0 | H22: =+C22 -> 0 | I22: =IFERROR(+H22/B22,"") | J22: =-SUMIFS(Ordenes!X$2:X$1275,Ordenes!AF$2:AF$1275,MONTH(A22 &17),Ordenes!AE$2:AE$1275,A$17) -> 0
A23: Junio | B23: =SUMIFS(Ordenes!R$2:R$1275,Ordenes!AF$2:AF$1275,MONTH(A23 &1),Ordenes!AE$2:AE$1275,A$17) -> 0 | C23: =+B23-'Costos Fijos'!L24 -> 0 | D23: =IFERROR(1-(C23/B23),"") | E23: =COUNTIFS(Ordenes!V:V,MONTH(A23 &17),Ordenes!AC:AC,A$17) -> 0 | F23: =COUNTIFS(Ordenes!W:W,MONTH(A23 &17),Ordenes!AD:AD,A$17) -> 0 | G23: =B23-C23 -> 0 | H23: =+C23 -> 0 | I23: =IFERROR(+H23/B23,"") | J23: =-SUMIFS(Ordenes!X$2:X$1275,Ordenes!AF$2:AF$1275,MONTH(A23 &17),Ordenes!AE$2:AE$1275,A$17) -> 0
A24: Julio | B24: =SUMIFS(Ordenes!R$2:R$1275,Ordenes!AF$2:AF$1275,MONTH(A24 &1),Ordenes!AE$2:AE$1275,A$17) -> 0 | C24: =+B24-'Costos Fijos'!L25 -> 0 | D24: =IFERROR(1-(C24/B24),"") | E24: =COUNTIFS(Ordenes!V:V,MONTH(A24 &17),Ordenes!AC:AC,A$17) -> 0 | F24: =COUNTIFS(Ordenes!W:W,MONTH(A24 &17),Ordenes!AD:AD,A$17) -> 0 | G24: =B24-C24 -> 0 | H24: =+C24 -> 0 | I24: =IFERROR(+H24/B24,"") | J24: =-SUMIFS(Ordenes!X$2:X$1275,Ordenes!AF$2:AF$1275,MONTH(A24 &17),Ordenes!AE$2:AE$1275,A$17) -> 0
A25: Agosto | B25: =SUMIFS(Ordenes!R$2:R$1275,Ordenes!AF$2:AF$1275,MONTH(A25 &1),Ordenes!AE$2:AE$1275,A$17) -> 0 | C25: =+B25-'Costos Fijos'!L26 -> 0 | D25: =IFERROR(1-(C25/B25),"") | E25: =COUNTIFS(Ordenes!V:V,MONTH(A25 &17),Ordenes!AC:AC,A$17) -> 0 | F25: =COUNTIFS(Ordenes!W:W,MONTH(A25 &17),Ordenes!AD:AD,A$17) -> 0 | G25: =B25-C25 -> 0 | H25: =+C25 -> 0 | I25: =IFERROR(+H25/B25,"") | J25: =-SUMIFS(Ordenes!X$2:X$1275,Ordenes!AF$2:AF$1275,MONTH(A25 &17),Ordenes!AE$2:AE$1275,A$17) -> 0
A26: Septiembre | B26: =SUMIFS(Ordenes!R$2:R$1275,Ordenes!AF$2:AF$1275,MONTH(A26 &1),Ordenes!AE$2:AE$1275,A$17) -> 0 | C26: =+B26-'Costos Fijos'!L27 -> 0 | D26: =IFERROR(1-(C26/B26),"") | E26: =COUNTIFS(Ordenes!V:V,MONTH(A26 &17),Ordenes!AC:AC,A$17) -> 0 | F26: =COUNTIFS(Ordenes!W:W,MONTH(A26 &17),Ordenes!AD:AD,A$17) -> 0 | G26: =B26-C26 -> 0 | H26: =+C26 -> 0 | I26: =IFERROR(+H26/B26,"") | J26: =-SUMIFS(Ordenes!X$2:X$1275,Ordenes!AF$2:AF$1275,MONTH(A26 &17),Ordenes!AE$2:AE$1275,A$17) -> 0
A27: Octubre | B27: =SUMIFS(Ordenes!R$2:R$1275,Ordenes!AF$2:AF$1275,MONTH(A27 &1),Ordenes!AE$2:AE$1275,A$17) -> 0 | C27: =+B27-'Costos Fijos'!L28 -> 0 | D27: =IFERROR(1-(C27/B27),"") | E27: =COUNTIFS(Ordenes!V:V,MONTH(A27 &17),Ordenes!AC:AC,A$17) -> 0 | F27: =COUNTIFS(Ordenes!W:W,MONTH(A27 &17),Ordenes!AD:AD,A$17) -> 0 | G27: =B27-C27 -> 0 | H27: =+C27 -> 0 | I27: =IFERROR(+H27/B27,"") | J27: =-SUMIFS(Ordenes!X$2:X$1275,Ordenes!AF$2:AF$1275,MONTH(A27 &17),Ordenes!AE$2:AE$1275,A$17) -> 0 | P27: =P13+H30-J30 -> 4856091.3
A28: Noviembre | B28: =SUMIFS(Ordenes!R$2:R$1275,Ordenes!AF$2:AF$1275,MONTH(A28 &1),Ordenes!AE$2:AE$1275,A$17) -> 0 | C28: =+B28-'Costos Fijos'!L29 -> 0 | D28: =IFERROR(1-(C28/B28),"") | E28: =COUNTIFS(Ordenes!V:V,MONTH(A28 &17),Ordenes!AC:AC,A$17) -> 0 | F28: =COUNTIFS(Ordenes!W:W,MONTH(A28 &17),Ordenes!AD:AD,A$17) -> 0 | G28: =B28-C28 -> 0 | H28: =+C28 -> 0 | I28: =IFERROR(+H28/B28,"") | J28: =-SUMIFS(Ordenes!X$2:X$1275,Ordenes!AF$2:AF$1275,MONTH(A28 &17),Ordenes!AE$2:AE$1275,A$17) -> 0 | O28: EQUIPOS 2024 COBRADOS EN 2025
A29: Diciembre | B29: =SUMIFS(Ordenes!R$2:R$1275,Ordenes!AF$2:AF$1275,MONTH(A29 &1),Ordenes!AE$2:AE$1275,A$17) -> 0 | C29: =+B29-'Costos Fijos'!L30 -> 0 | D29: =IFERROR(1-(C29/B29),"") | E29: =COUNTIFS(Ordenes!V:V,MONTH(A29 &17),Ordenes!AC:AC,A$17) -> 0 | F29: =COUNTIFS(Ordenes!W:W,MONTH(A29 &17),Ordenes!AD:AD,A$17) -> 0 | G29: =B29-C29 -> 0 | H29: =+C29 -> 0 | I29: =IFERROR(+H29/B29,"") | J29: =-SUMIFS(Ordenes!X$2:X$1275,Ordenes!AF$2:AF$1275,MONTH(A29 &17),Ordenes!AE$2:AE$1275,A$17) -> 0 | O29: TOTAL REAL EN CAJA | P29: =P27+P28+L30-K30 -> 6216858.4
A30: ANUAL | B30: =SUM(B18:B29) -> 16570880 | C30: =SUM(C18:C29) -> 9388547.8 | D30: =IFERROR(1-(C30/B30),"") -> 0.43343095 | E30: =SUM(E18:E29) -> 86 | F30: =SUM(F18:F29) -> 81 | G30: =B30-C30 -> 7182332.2 | H30: =+C30 -> 9388547.8 | I30: =IFERROR(+H30/B30,"") -> 0.56656905 | J30: =SUM(J18:J29) -> 2846600 | K30: =SUM(K18:K29) -> 1250000 | L30: =SUM(L18:L29) -> 2610767.1 | M30: =SUM(M18:M29)+M14 -> 7089.03 | O30: DIEFERENCIA CON CAJA BRC | P30: =P29-'[4]2025'!$P$500 -> 0.49
B31: =(B30/B14)-1 -> -0.53043139 | C31: =(C30/C14)-1 -> 0.91100887

Sheet Hoja4
